Workbook

Sheet Приборы учета
A1: Организация | B1: Номер помещения | C1: № счетчика | D1: Тип ресурса | E1: Коэффициент трансформации | F1: Показания на конец декабря | G1: Показания на конец января | H1: Потребление
A2: АО Эпсилон | B2: СТ-01,65 (WB) | C2: 23_11081511 | D2: ХВС | F2: 1.241 | G2: 1.882 | H2: =G2-F2 -> 0.641
C3: 23_11031554 | D3: ГВС | F3: 0.316 | G3: 0.407 | H3: =G3-F3 -> 0.091
C4: 47824789-23 | D4: Электричество | E4: 1 | F4: 163.8 | G4: 325.91 | H4: =G4-F4 -> 162.11
A5: АО Эпсилон | B5: СТ-01,73 (Monte Luxe) | C5: 25_15402002 | D5: ХВС | F5: 0.215 | G5: 0.215 | H5: =G5-F5 -> 0
C6: 25_15399810 | D6: ГВС | F6: 0.006 | G6: 0.006 | H6: =G6-F6 -> 0
C7: 48028167-23 | D7: Электричество | E7: 1 | F7: 4.47 | G7: 4.47 | H7: =G7-F7 -> 0
A8: АО Эпсилон | B8: СТ-6, 7, 8 (XFIT) | C8: 10960076 | D8: ХВС | F8: 0.01 | G8: 16.748 | H8: =G8-F8 -> 16.738
C9: 47947358-23 | D9: Электричество | E9: 120 | F9: 4698.17 | G9: 4752.17 | H9: =G9-F9 -> 54
C10: 47881859-23 | D10: Электричество | E10: 1 | F10: 2.81 | G10: 2.81 | H10: =G10-F10 -> 0
A11: АО Эпсилон | B11: СТ-06,28 (Айконлаб) | C11: 25_15145897 | D11: ХВС | F11: 4.897 | G11: 5.529 | H11: =G11-F11 -> 0.632
C12: 25_15145868 | D12: ГВС | F12: 0.249 | G12: 0.549 | H12: =G12-F12 -> 0.3
C13: 51662071-25 | D13: Электричество | E13: 1 | F13: 181.86 | G13: 316.9 | H13: =G13-F13 -> 135.04
A14: АО Эпсилон | B14: СТ-06,30 (СИТИМАРКЕТ) | C14: 51845989 | D14: Электричество | E14: 1 | F14: 13.74 | G14: 13.74 | H14: =G14-F14 -> 0
A15: АО Эпсилон | B15: СТ-06,34 (Surf Coffee) | C15: 25_15238052 | D15: ХВС | F15: 3.496 | G15: 3.681 | H15: =G15-F15 -> 0.185
C16: 25_15145861 | D16: ГВС | F16: 0.151 | G16: 0.162 | H16: =G16-F16 -> 0.011
C17: 51845988-25 | D17: Электричество | E17: 1 | F17: 300.07 | G17: 359.63 | H17: =G17-F17 -> 59.56
A18: АО Эпсилон | B18: СТ-06,38 (Лепим и Варим) | C18: 11081526 | D18: ХВС | F18: 0.04 | G18: 0.04 | H18: =G18-F18 -> 0
C19: 11081527 | D19: ГВС | F19: 0.013 | G19: 4.016 | H19: =G19-F19 -> 4.003
C20: 48028190 | D20: Электричество | E20: 1 | F20: 0 | G20: 33.46 | H20: =G20-F20 -> 33.46
C21: 47946993 | D21: Электричество | E21: 40 | F21: 0 | G21: 0.91 | H21: =G21-F21 -> 0.91
A22: АО Эпсилон | B22: СТ-06,39 (PHO NGON) | C22: 23_09540666 | D22: ХВС | F22: 9.234 | G22: 10.921 | H22: =G22-F22 -> 1.687
C23: 23_11081507 | D23: ГВС | F23: 0.032 | G23: 0.032 | H23: =G23-F23 -> 0
C24: 49555472-24 | D24: Электричество | E24: 50 | F24: 9.03 | G24: 10.91 | H24: =G24-F24 -> 1.88
A25: АО Эпсилон | B25: СТ-06,31 (СЭТ) | C25: 25_15141424 | D25: ХВС | F25: 1.34 | G25: 1.34 | H25: =G25-F25 -> 0
C26: 25_15140861 | D26: ГВС | F26: 0.419 | G26: 0.419 | H26: =G26-F26 -> 0
C27: 48028177-23 | D27: Электричество | E27: 1 | F27: 107.82 | G27: 107.82 | H27: =G27-F27 -> 0
A28: АО Эпсилон | B28: СТ-06,29 (Аптека 36,6) | C28: 48028229-23 | D28: Электричество | E28: 1 | F28: 569.2 | G28: 569.2 | H28: =G28-F28 -> 0
A29: АО Эпсилон | B29: СТ-06,35 (TAPIOKA) | C29: 25_15238042 | D29: ХВС | F29: 0.377 | G29: 0.377 | H29: =G29-F29 -> 0
C30: 25_15145848 | D30: ГВС | F30: 0.031 | G30: 0.031 | H30: =G30-F30 -> 0
C31: 47883613-23 | D31: Электричество | E31: 1 | F31: 9.16 | G31: 19.07 | H31: =G31-F31 -> 9.91
A32: ООО «Скайсити Эстейт Менеджмент» | B32: СТ-06,25 | C32: 11573565 | D32: ХВС | F32: 0 | G32: 0 | H32: =G32-F32 -> 0
C33: 23_11081985 | D33: ГВС | F33: 0.016 | G33: 0.016 | H33: =G33-F33 -> 0
C34: 45336943_21 | D34: Электричество | E34: 1 | F34: 0.33 | G34: 0.33 | H34: =G34-F34 -> 0
A35: ИП Чувелёв Алексей Николаевич | B35: Т2-12,16 | C35: 23_10968075 | D35: ХВС | F35: 1.33 | G35: 2.577 | H35: =G35-F35 -> 1.247
C36: 23_10968965 | D36: ГВС | F36: 0.174 | G36: 0.174 | H36: =G36-F36 -> 0
C37: 48028983_23 | D37: Электричество | E37: 1 | F37: 24.78 | G37: 92.67 | H37: =G37-F37 -> 67.89
A38: ООО «ПМ-1» | B38: Т2-12,17 | C38: 23_10971265 | D38: ХВС | F38: 0.039 | G38: 0.039 | H38: =G38-F38 -> 0
C39: 23_10968073 | D39: ГВС | F39: 0.398 | G39: 0.398 | H39: =G39-F39 -> 0
C40: 47883996_23 | D40: Электричество | E40: 1 | F40: 2818.89 | G40: 2818.89 | H40: =G40-F40 -> 0
...

Sheet Электроэнергия
A1: № счетчика | B1: Показание на начало периода | C1: Показание на конец периода | D1: Коэфф. тр. | E1: Потребление, кВт*ч
A2: ='Приборы учета'!$C$4 -> 47824789-23 | B2: ='Приборы учета'!F4 -> 163.8 | C2: ='Приборы учета'!G4 -> 325.91 | D2: ='Приборы учета'!$E$4 -> 1 | E2: =D2*(C2-B2) -> 162.11
A3: ='Приборы учета'!$C$7 -> 48028167-23 | B3: ='Приборы учета'!F7 -> 4.47 | C3: ='Приборы учета'!G7 -> 4.47 | D3: ='Приборы учета'!$E$7 -> 1 | E3: =D3*(C3-B3) -> 0
A4: ='Приборы учета'!C9 -> 47947358-23 | B4: ='Приборы учета'!F9 -> 4698.17 | C4: ='Приборы учета'!G9 -> 4752.17 | D4: ='Приборы учета'!E9 -> 120 | E4: =D4*(C4-B4) -> 6480
A5: ='Приборы учета'!C10 -> 47881859-23 | B5: ='Приборы учета'!F10 -> 2.81 | C5: ='Приборы учета'!G10 -> 2.81 | D5: ='Приборы учета'!E10 -> 1 | E5: =D5*(C5-B5) -> 0
A6: ='Приборы учета'!C13 -> 51662071-25 | B6: ='Приборы учета'!F13 -> 181.86 | C6: ='Приборы учета'!G13 -> 316.9 | D6: ='Приборы учета'!E13 -> 1 | E6: =D6*(C6-B6) -> 135.04
A7: ='Приборы учета'!C14 -> 51845989 | B7: ='Приборы учета'!F14 -> 13.74 | C7: ='Приборы учета'!G14 -> 13.74 | D7: ='Приборы учета'!E14 -> 1 | E7: =D7*(C7-B7) -> 0
A8: ='Приборы учета'!$C$17 -> 51845988-25 | B8: ='Приборы учета'!F17 -> 300.07 | C8: ='Приборы учета'!G17 -> 359.63 | D8: ='Приборы учета'!$E$17 -> 1 | E8: =D8*(C8-B8) -> 59.56
A9: ='Приборы учета'!C20 -> 48028190 | B9: ='Приборы учета'!F20 -> 0 | C9: ='Приборы учета'!G20 -> 33.46 | D9: ='Приборы учета'!E20 -> 1 | E9: =D9*(C9-B9) -> 33.46
A10: ='Приборы учета'!C21 -> 47946993 | B10: ='Приборы учета'!F21 -> 0 | C10: ='Приборы учета'!G21 -> 0.91 | D10: ='Приборы учета'!E21 -> 40 | E10: =D10*(C10-B10) -> 36.4
A11: ='Приборы учета'!$C$24 -> 49555472-24 | B11: ='Приборы учета'!F24 -> 9.03 | C11: ='Приборы учета'!G24 -> 10.91 | D11: ='Приборы учета'!$E$24 -> 50 | E11: =D11*(C11-B11) -> 94
A12: ='Приборы учета'!C27 -> 48028177-23 | B12: ='Приборы учета'!F27 -> 107.82 | C12: ='Приборы учета'!G27 -> 107.82 | D12: ='Приборы учета'!E27 -> 1 | E12: =D12*(C12-B12) -> 0
A13: ='Приборы учета'!C28 -> 48028229-23 | B13: ='Приборы учета'!F28 -> 569.2 | C13: ='Приборы учета'!G28 -> 569.2 | D13: ='Приборы учета'!E28 -> 1 | E13: =D13*(C13-B13) -> 0
A14: ='Приборы учета'!$C$31 -> 47883613-23 | B14: ='Приборы учета'!F31 -> 9.16 | C14: ='Приборы учета'!G31 -> 19.07 | D14: ='Приборы учета'!$E$31 -> 1 | E14: =D14*(C14-B14) -> 9.91
A15: ='Приборы учета'!$C$34 -> 45336943_21 | B15: ='Приборы учета'!F34 -> 0.33 | C15: ='Приборы учета'!G34 -> 0.33 | D15: ='Приборы учета'!$E$34 -> 1 | E15: =D15*(C15-B15) -> 0
A16: ='Приборы учета'!$C$37 -> 48028983_23 | B16: ='Приборы учета'!F37 -> 24.78 | C16: ='Приборы учета'!G37 -> 92.67 | D16: ='Приборы учета'!$E$37 -> 1 | E16: =D16*(C16-B16) -> 67.89
A17: ='Приборы учета'!$C$40 -> 47883996_23 | B17: ='Приборы учета'!F40 -> 2818.89 | C17: ='Приборы учета'!G40 -> 2818.89 | D17: ='Приборы учета'!$E$40 -> 1 | E17: =D17*(C17-B17) -> 0
A18: ='Приборы учета'!$C$43 -> 48028502_23 | B18: ='Приборы учета'!F43 -> 0.78 | C18: ='Приборы учета'!G43 -> 0.78 | D18: ='Приборы учета'!$E$43 -> 1 | E18: =D18*(C18-B18) -> 0
A19: ='Приборы учета'!$C$46 -> 40821843 | B19: ='Приборы учета'!F46 -> 0.67 | C19: ='Приборы учета'!G46 -> 0.67 | D19: ='Приборы учета'!$E$46 -> 16 | E19: =D19*(C19-B19) -> 0
A20: ='Приборы учета'!$C$49 -> 48021837 | B20: ='Приборы учета'!F49 -> 1.73 | C20: ='Приборы учета'!G49 -> 1.73 | D20: ='Приборы учета'!$E$49 -> 1 | E20: =D20*(C20-B20) -> 0
A21: ='Приборы учета'!$C$52 -> 48021878 | B21: ='Приборы учета'!F52 -> 1.21 | C21: ='Приборы учета'!G52 -> 1.21 | D21: ='Приборы учета'!$E$52 -> 16 | E21: =D21*(C21-B21) -> 0
A22: ='Приборы учета'!$C$55 -> 48028483 | B22: ='Приборы учета'!F55 -> 15.02 | C22: ='Приборы учета'!G55 -> 211.09 | D22: ='Приборы учета'!$E$55 -> 1 | E22: =D22*(C22-B22) -> 196.07
A23: ='Приборы учета'!$C$58 -> 47944034 | B23: ='Приборы учета'!F58 -> 3.02 | C23: ='Приборы учета'!G58 -> 3.02 | D23: ='Приборы учета'!$E$58 -> 1 | E23: =D23*(C23-B23) -> 0
A24: ='Приборы учета'!$C$61 -> 48028578 | B24: ='Приборы учета'!F61 -> 1.27 | C24: ='Приборы учета'!G61 -> 1.27 | D24: ='Приборы учета'!$E$61 -> 1 | E24: =D24*(C24-B24) -> 0
A25: ='Приборы учета'!$C$64 -> 47770778 | B25: ='Приборы учета'!F64 -> 0.7 | C25: ='Приборы учета'!G64 -> 477.72 | D25: ='Приборы учета'!$E$64 -> 1 | E25: =D25*(C25-B25) -> 477.02
A26: ='Приборы учета'!$C$67 -> 48028009 | B26: ='Приборы учета'!F67 -> 2.85 | C26: ='Приборы учета'!G67 -> 2.85 | D26: ='Приборы учета'!$E$67 -> 1 | E26: =D26*(C26-B26) -> 0
A27: ='Приборы учета'!$C$70 -> 48027985 | B27: ='Приборы учета'!F70 -> 2.49 | C27: ='Приборы учета'!G70 -> 2.49 | D27: ='Приборы учета'!$E$70 -> 1 | E27: =D27*(C27-B27) -> 0
A28: ='Приборы учета'!$C$73 -> 47132930 | B28: ='Приборы учета'!F73 -> 3.24 | C28: ='Приборы учета'!G73 -> 3.24 | D28: ='Приборы учета'!$E$73 -> 1 | E28: =D28*(C28-B28) -> 0
A29: ='Приборы учета'!$C$76 -> 47340969 | B29: ='Приборы учета'!F76 -> 1.03 | C29: ='Приборы учета'!G76 -> 1.03 | D29: ='Приборы учета'!$E$76 -> 1 | E29: =D29*(C29-B29) -> 0
A30: ='Приборы учета'!$C$79 -> 47314616 | B30: ='Приборы учета'!F79 -> 1.1 | C30: ='Приборы учета'!G79 -> 1.1 | D30: ='Приборы учета'!$E$79 -> 1 | E30: =D30*(C30-B30) -> 0
A31: ='Приборы учета'!$C$82 -> 47314696 | B31: ='Приборы учета'!F82 -> 1.78 | C31: ='Приборы учета'!G82 -> 1.78 | D31: ='Приборы учета'!$E$82 -> 1 | E31: =D31*(C31-B31) -> 0
A32: ='Приборы учета'!$C$85 -> 47315653 | B32: ='Приборы учета'!F85 -> 2.72 | C32: ='Приборы учета'!G85 -> 2.72 | D32: ='Приборы учета'!$E$85 -> 1 | E32: =D32*(C32-B32) -> 0
A33: ='Приборы учета'!$C$88 -> 47315655 | B33: ='Приборы учета'!F88 -> 0.93 | C33: ='Приборы учета'!G88 -> 3.53 | D33: ='Приборы учета'!$E$88 -> 1 | E33: =D33*(C33-B33) -> 2.6
A34: ='Приборы учета'!$C$91 -> 48021964 | B34: ='Приборы учета'!F91 -> 0.73 | C34: ='Приборы учета'!G91 -> 0.73 | D34: ='Приборы учета'!$E$91 -> 1 | E34: =D34*(C34-B34) -> 0
A35: ='Приборы учета'!$C$94 -> 48021857 | B35: ='Приборы учета'!F94 -> 0.81 | C35: ='Приборы учета'!G94 -> 0.81 | D35: ='Приборы учета'!$E$94 -> 1 | E35: =D35*(C35-B35) -> 0
A36: ='Приборы учета'!$C$97 -> 47823890 | B36: ='Приборы учета'!F97 -> 2.37 | C36: ='Приборы учета'!G97 -> 2.37 | D36: ='Приборы учета'!$E$97 -> 1 | E36: =D36*(C36-B36) -> 0
A37: ='Приборы учета'!$C$100 -> 47823868 | B37: ='Приборы учета'!F100 -> 0.99 | C37: ='Приборы учета'!G100 -> 0.99 | D37: ='Приборы учета'!$E$100 -> 1 | E37: =D37*(C37-B37) -> 0
A38: ='Приборы учета'!$C$103 -> 47944550 | B38: ='Приборы учета'!F103 -> 0.71 | C38: ='Приборы учета'!G103 -> 0.71 | D38: ='Приборы учета'!$E$103 -> 1 | E38: =D38*(C38-B38) -> 0
A39: ='Приборы учета'!$C$106 -> 47314611 | B39: ='Приборы учета'!F106 -> 133.97 | C39: ='Приборы учета'!G106 -> 219.76 | D39: ='Приборы учета'!$E$106 -> 1 | E39: =D39*(C39-B39) -> 85.79
A40: ='Приборы учета'!$C$109 -> 48028332 | B40: ='Приборы учета'!F109 -> 0.75 | C40: ='Приборы учета'!G109 -> 0.75 | D40: ='Приборы учета'!$E$109 -> 1 | E40: =D40*(C40-B40) -> 0
...

Sheet ХВС
A1: № счетчика | B1: Показание на начало периода | C1: Показание на конец периода | D1: Потребление, м³
A2: ='Приборы учета'!$C$2 -> 23_11081511 | B2: ='Приборы учета'!$F$2 -> 1.241 | C2: ='Приборы учета'!$G$2 -> 1.882 | D2: =C2-B2 -> 0.641
A3: ='Приборы учета'!$C$5 -> 25_15402002 | B3: ='Приборы учета'!$F$5 -> 0.215 | C3: ='Приборы учета'!$G$5 -> 0.215 | D3: =C3-B3 -> 0
A4: ='Приборы учета'!$C$8 -> 10960076 | B4: ='Приборы учета'!$F$8 -> 0.01 | C4: ='Приборы учета'!$G$8 -> 16.748 | D4: =C4-B4 -> 16.738
A5: ='Приборы учета'!$C$11 -> 25_15145897 | B5: ='Приборы учета'!$F$11 -> 4.897 | C5: ='Приборы учета'!$G$11 -> 5.529 | D5: =C5-B5 -> 0.632
A6: ='Приборы учета'!$C$15 -> 25_15238052 | B6: ='Приборы учета'!$F$15 -> 3.496 | C6: ='Приборы учета'!$G$15 -> 3.681 | D6: =C6-B6 -> 0.185
A7: ='Приборы учета'!$C$18 -> 11081526 | B7: ='Приборы учета'!$F$18 -> 0.04 | C7: ='Приборы учета'!$G$18 -> 0.04 | D7: =C7-B7 -> 0
A8: ='Приборы учета'!$C$22 -> 23_09540666 | B8: ='Приборы учета'!$F$22 -> 9.234 | C8: ='Приборы учета'!$G$22 -> 10.921 | D8: =C8-B8 -> 1.687
A9: ='Приборы учета'!$C$25 -> 25_15141424 | B9: ='Приборы учета'!$F$25 -> 1.34 | C9: ='Приборы учета'!$G$25 -> 1.34 | D9: =C9-B9 -> 0
A10: ='Приборы учета'!$C$29 -> 25_15238042 | B10: ='Приборы учета'!$F$29 -> 0.377 | C10: ='Приборы учета'!$G$29 -> 0.377 | D10: =C10-B10 -> 0
A11: ='Приборы учета'!$C$32 -> 11573565 | B11: ='Приборы учета'!$F$32 -> 0 | C11: ='Приборы учета'!$G$32 -> 0 | D11: =C11-B11 -> 0
A12: ='Приборы учета'!$C$35 -> 23_10968075 | B12: ='Приборы учета'!$F$35 -> 1.33 | C12: ='Приборы учета'!$G$35 -> 2.577 | D12: =C12-B12 -> 1.247
A13: ='Приборы учета'!$C$38 -> 23_10971265 | B13: ='Приборы учета'!$F$38 -> 0.039 | C13: ='Приборы учета'!$G$38 -> 0.039 | D13: =C13-B13 -> 0
A14: ='Приборы учета'!$C$41 -> 23_10971258 | B14: ='Приборы учета'!$F$41 -> 0.108 | C14: ='Приборы учета'!$G$41 -> 0.108 | D14: =C14-B14 -> 0
A15: ='Приборы учета'!$C$44 -> 23_10968018 | B15: ='Приборы учета'!$F$44 -> 0.009 | C15: ='Приборы учета'!$G$44 -> 0.009 | D15: =C15-B15 -> 0
A16: ='Приборы учета'!$C$47 -> 23_11039674 | B16: ='Приборы учета'!$F$47 -> 38.22 | C16: ='Приборы учета'!$G$47 -> 38.22 | D16: =C16-B16 -> 0
A17: ='Приборы учета'!$C$50 -> 23_10971112 | B17: ='Приборы учета'!$F$50 -> 0.004 | C17: ='Приборы учета'!$G$50 -> 0.004 | D17: =C17-B17 -> 0
A18: ='Приборы учета'!$C$53 -> 11039489 | B18: ='Приборы учета'!$F$53 -> 0.224 | C18: ='Приборы учета'!$G$53 -> 6.28 | D18: =C18-B18 -> 6.056
A19: ='Приборы учета'!$C$56 -> 11039677 | B19: ='Приборы учета'!$F$56 -> 0.044 | C19: ='Приборы учета'!$G$56 -> 0.044 | D19: =C19-B19 -> 0
A20: ='Приборы учета'!$C$59 -> 11081562 | B20: ='Приборы учета'!$F$59 -> 0.01 | C20: ='Приборы учета'!$G$59 -> 0.01 | D20: =C20-B20 -> 0
A21: ='Приборы учета'!$C$62 -> 10970954 | B21: ='Приборы учета'!$F$62 -> 0.009 | C21: ='Приборы учета'!$G$62 -> 3.109 | D21: =C21-B21 -> 3.1
A22: ='Приборы учета'!$C$65 -> 10966621 | B22: ='Приборы учета'!$F$65 -> 0.17 | C22: ='Приборы учета'!$G$65 -> 0.17 | D22: =C22-B22 -> 0
A23: ='Приборы учета'!$C$68 -> 10967350 | B23: ='Приборы учета'!$F$68 -> 0.21 | C23: ='Приборы учета'!$G$68 -> 0.21 | D23: =C23-B23 -> 0
A24: ='Приборы учета'!$C$71 -> 11466468 | B24: ='Приборы учета'!$F$71 -> 0.01 | C24: ='Приборы учета'!$G$71 -> 0.01 | D24: =C24-B24 -> 0
A25: ='Приборы учета'!$C$74 -> 11467006 | B25: ='Приборы учета'!$F$74 -> 0.554 | C25: ='Приборы учета'!$G$74 -> 0.554 | D25: =C25-B25 -> 0
A26: ='Приборы учета'!$C$77 -> 10968110 | B26: ='Приборы учета'!$F$77 -> 0.18 | C26: ='Приборы учета'!$G$77 -> 0.18 | D26: =C26-B26 -> 0
A27: ='Приборы учета'!$C$80 -> 11466755 | B27: ='Приборы учета'!$F$80 -> 0.69 | C27: ='Приборы учета'!$G$80 -> 0.69 | D27: =C27-B27 -> 0
A28: ='Приборы учета'!$C$83 -> 11466211 | B28: ='Приборы учета'!$F$83 -> 0.01 | C28: ='Приборы учета'!$G$83 -> 0.01 | D28: =C28-B28 -> 0
A29: ='Приборы учета'!$C$86 -> 11467281 | B29: ='Приборы учета'!$F$86 -> 0.1 | C29: ='Приборы учета'!$G$86 -> 0.1 | D29: =C29-B29 -> 0
A30: ='Приборы учета'!$C$89 -> 11466808 | B30: ='Приборы учета'!$F$89 -> 0.13 | C30: ='Приборы учета'!$G$89 -> 0.13 | D30: =C30-B30 -> 0
A31: ='Приборы учета'!$C$92 -> 11466273 | B31: ='Приборы учета'!$F$92 -> 76.7 | C31: ='Приборы учета'!$G$92 -> 76.7 | D31: =C31-B31 -> 0
A32: ='Приборы учета'!$C$95 -> 11466271 | B32: ='Приборы учета'!$F$95 -> 0.26 | C32: ='Приборы учета'!$G$95 -> 0.26 | D32: =C32-B32 -> 0
A33: ='Приборы учета'!$C$98 -> 10967379 | B33: ='Приборы учета'!$F$98 -> 0.045 | C33: ='Приборы учета'!$G$98 -> 0.045 | D33: =C33-B33 -> 0
A34: ='Приборы учета'!$C$101 -> 11466271 | B34: ='Приборы учета'!$F$101 -> 0.42 | C34: ='Приборы учета'!$G$101 -> 0.42 | D34: =C34-B34 -> 0
A35: ='Приборы учета'!$C$104 -> 10970926 | B35: ='Приборы учета'!$F$104 -> 6.53 | C35: ='Приборы учета'!$G$104 -> 9.419 | D35: =C35-B35 -> 2.889
A36: ='Приборы учета'!$C$107 -> 12182321 | B36: ='Приборы учета'!$F$107 -> 0.019 | C36: ='Приборы учета'!$G$107 -> 0.019 | D36: =C36-B36 -> 0
A37: ='Приборы учета'!$C$110 -> 10969059 | B37: ='Приборы учета'!$F$110 -> 0 | C37: ='Приборы учета'!$G$110 -> 0 | D37: =C37-B37 -> 0
A38: ='Приборы учета'!$C$113 -> 10971175 | B38: ='Приборы учета'!$F$113 -> 0.22 | C38: ='Приборы учета'!$G$113 -> 0.22 | D38: =C38-B38 -> 0
A39: ='Приборы учета'!$C$116 -> 10971557 | B39: ='Приборы учета'!$F$116 -> 1.27 | C39: ='Приборы учета'!$G$116 -> 1.27 | D39: =C39-B39 -> 0
A40: ='Приборы учета'!$C$119 -> 10971296 | B40: ='Приборы учета'!$F$119 -> 0.514 | C40: ='Приборы учета'!$G$119 -> 0.514 | D40: =C40-B40 -> 0
...

Sheet ГВС
A1: № счетчика | B1: Показание на начало периода | C1: Показание на конец периода | D1: Потребление, м³
A2: ='Приборы учета'!$C$3 -> 23_11031554 | B2: ='Приборы учета'!F3 -> 0.316 | C2: ='Приборы учета'!G3 -> 0.407 | D2: =C2-B2 -> 0.091
A3: ='Приборы учета'!$C$6 -> 25_15399810 | B3: ='Приборы учета'!F6 -> 0.006 | C3: ='Приборы учета'!G6 -> 0.006 | D3: =C3-B3 -> 0
A4: ='Приборы учета'!$C$12 -> 25_15145868 | B4: ='Приборы учета'!F12 -> 0.249 | C4: ='Приборы учета'!G12 -> 0.549 | D4: =C4-B4 -> 0.3
A5: ='Приборы учета'!$C$16 -> 25_15145861 | B5: ='Приборы учета'!F16 -> 0.151 | C5: ='Приборы учета'!G16 -> 0.162 | D5: =C5-B5 -> 0.011
A6: ='Приборы учета'!$C$19 -> 11081527 | B6: ='Приборы учета'!F19 -> 0.013 | C6: ='Приборы учета'!G19 -> 4.016 | D6: =C6-B6 -> 4.003
A7: ='Приборы учета'!$C$23 -> 23_11081507 | B7: ='Приборы учета'!F23 -> 0.032 | C7: ='Приборы учета'!G23 -> 0.032 | D7: =C7-B7 -> 0
A8: ='Приборы учета'!$C$26 -> 25_15140861 | B8: ='Приборы учета'!F26 -> 0.419 | C8: ='Приборы учета'!G26 -> 0.419 | D8: =C8-B8 -> 0
A9: ='Приборы учета'!$C$30 -> 25_15145848 | B9: ='Приборы учета'!F30 -> 0.031 | C9: ='Приборы учета'!G30 -> 0.031 | D9: =C9-B9 -> 0
A10: ='Приборы учета'!$C$33 -> 23_11081985 | B10: ='Приборы учета'!F33 -> 0.016 | C10: ='Приборы учета'!G33 -> 0.016 | D10: =C10-B10 -> 0
A11: ='Приборы учета'!$C$36 -> 23_10968965 | B11: ='Приборы учета'!F36 -> 0.174 | C11: ='Приборы учета'!G36 -> 0.174 | D11: =C11-B11 -> 0
A12: ='Приборы учета'!$C$39 -> 23_10968073 | B12: ='Приборы учета'!F39 -> 0.398 | C12: ='Приборы учета'!G39 -> 0.398 | D12: =C12-B12 -> 0
A13: ='Приборы учета'!$C$42 -> 23_10970618 | B13: ='Приборы учета'!F42 -> 0.01 | C13: ='Приборы учета'!G42 -> 0.01 | D13: =C13-B13 -> 0
A14: ='Приборы учета'!$C$45 -> 23_10971551 | B14: ='Приборы учета'!F45 -> 0.008 | C14: ='Приборы учета'!G45 -> 0.008 | D14: =C14-B14 -> 0
A15: ='Приборы учета'!$C$48 -> 23_10968020 | B15: ='Приборы учета'!F48 -> 0.077 | C15: ='Приборы учета'!G48 -> 0.077 | D15: =C15-B15 -> 0
A16: ='Приборы учета'!$C$51 -> 23_10967997 | B16: ='Приборы учета'!F51 -> 0.008 | C16: ='Приборы учета'!G51 -> 0.008 | D16: =C16-B16 -> 0
A17: ='Приборы учета'!$C$54 -> 11043830 | B17: ='Приборы учета'!F54 -> 0.046 | C17: ='Приборы учета'!G54 -> 0.46 | D17: =C17-B17 -> 0.414
A18: ='Приборы учета'!$C$57 -> 11039686 | B18: ='Приборы учета'!F57 -> 0.016 | C18: ='Приборы учета'!G57 -> 0.016 | D18: =C18-B18 -> 0
A19: ='Приборы учета'!$C$60 -> 11039709 | B19: ='Приборы учета'!F60 -> 0.01 | C19: ='Приборы учета'!G60 -> 0.01 | D19: =C19-B19 -> 0
A20: ='Приборы учета'!$C$63 -> 10972469 | B20: ='Приборы учета'!F63 -> 0.012 | C20: ='Приборы учета'!G63 -> 0.026 | D20: =C20-B20 -> 0.014
A21: ='Приборы учета'!$C$66 -> 10972533 | B21: ='Приборы учета'!F66 -> 0.4 | C21: ='Приборы учета'!G66 -> 0.4 | D21: =C21-B21 -> 0
A22: ='Приборы учета'!$C$69 -> 10968464 | B22: ='Приборы учета'!F69 -> 0.23 | C22: ='Приборы учета'!G69 -> 0.23 | D22: =C22-B22 -> 0
A23: ='Приборы учета'!$C$72 -> 11466533 | B23: ='Приборы учета'!F72 -> 0.015 | C23: ='Приборы учета'!G72 -> 0.015 | D23: =C23-B23 -> 0
A24: ='Приборы учета'!$C$75 -> 11081566 | B24: ='Приборы учета'!F75 -> 0.03 | C24: ='Приборы учета'!G75 -> 0.03 | D24: =C24-B24 -> 0
A25: ='Приборы учета'!$C$78 -> 10968587 | B25: ='Приборы учета'!F78 -> 0.06 | C25: ='Приборы учета'!G78 -> 0.06 | D25: =C25-B25 -> 0
A26: ='Приборы учета'!$C$81 -> 11466680 | B26: ='Приборы учета'!F81 -> 0.059 | C26: ='Приборы учета'!G81 -> 0.059 | D26: =C26-B26 -> 0
A27: ='Приборы учета'!$C$84 -> 9008723 | B27: ='Приборы учета'!F84 -> 0.01 | C27: ='Приборы учета'!G84 -> 0.01 | D27: =C27-B27 -> 0
A28: ='Приборы учета'!$C$87 -> 11466462 | B28: ='Приборы учета'!F87 -> 0.1 | C28: ='Приборы учета'!G87 -> 0.1 | D28: =C28-B28 -> 0
A29: ='Приборы учета'!$C$90 -> 11466666 | B29: ='Приборы учета'!F90 -> 0.15 | C29: ='Приборы учета'!G90 -> 0.15 | D29: =C29-B29 -> 0
A30: ='Приборы учета'!$C$93 -> 11466541 | B30: ='Приборы учета'!F93 -> 0.28 | C30: ='Приборы учета'!G93 -> 0.28 | D30: =C30-B30 -> 0
A31: ='Приборы учета'!$C$96 -> 11466544 | B31: ='Приборы учета'!F96 -> 0.08 | C31: ='Приборы учета'!G96 -> 0.08 | D31: =C31-B31 -> 0
A32: ='Приборы учета'!$C$99 -> 10970931 | B32: ='Приборы учета'!F99 -> 0.038 | C32: ='Приборы учета'!G99 -> 0.038 | D32: =C32-B32 -> 0
A33: ='Приборы учета'!$C$102 -> 11466269 | B33: ='Приборы учета'!F102 -> 0.16 | C33: ='Приборы учета'!G102 -> 0.16 | D33: =C33-B33 -> 0
A34: ='Приборы учета'!$C$105 -> 10967261 | B34: ='Приборы учета'!F105 -> 1.682 | C34: ='Приборы учета'!G105 -> 2.103 | D34: =C34-B34 -> 0.421
A35: ='Приборы учета'!$C$108 -> 12189381 | B35: ='Приборы учета'!F108 -> 0.049 | C35: ='Приборы учета'!G108 -> 0.049 | D35: =C35-B35 -> 0
A36: ='Приборы учета'!$C$111 -> 10971556 | B36: ='Приборы учета'!F111 -> 0 | C36: ='Приборы учета'!G111 -> 0 | D36: =C36-B36 -> 0
A37: ='Приборы учета'!$C$114 -> 10969710 | B37: ='Приборы учета'!F114 -> 0.26 | C37: ='Приборы учета'!G114 -> 0.26 | D37: =C37-B37 -> 0
A38: ='Приборы учета'!$C$117 -> 10971560 | B38: ='Приборы учета'!F117 -> 0.316 | C38: ='Приборы учета'!G117 -> 0.316 | D38: =C38-B38 -> 0
A39: ='Приборы учета'!$C$120 -> 10966630 | B39: ='Приборы учета'!F120 -> 0.36 | C39: ='Приборы учета'!G120 -> 0.36 | D39: =C39-B39 -> 0
A40: ='Приборы учета'!$C$123 -> 10971759 | B40: ='Приборы учета'!F123 -> 0.88 | C40: ='Приборы учета'!G123 -> 0.88 | D40: =C40-B40 -> 0
...
